[2024-02-16T10:01:59.748+0000] {taskinstance.py:1956} INFO - Dependencies all met for dep_context=non-requeueable deps ti=<TaskInstance: our_first_dag_v2.second_task manual__2024-02-16T10:01:57.550984+00:00 [queued]>
[2024-02-16T10:01:59.756+0000] {taskinstance.py:1956} INFO - Dependencies all met for dep_context=requeueable deps ti=<TaskInstance: our_first_dag_v2.second_task manual__2024-02-16T10:01:57.550984+00:00 [queued]>
[2024-02-16T10:01:59.756+0000] {taskinstance.py:2170} INFO - Starting attempt 1 of 6
[2024-02-16T10:01:59.771+0000] {taskinstance.py:2191} INFO - Executing <Task(BashOperator): second_task> on 2024-02-16 10:01:57.550984+00:00
[2024-02-16T10:01:59.776+0000] {standard_task_runner.py:60} INFO - Started process 584 to run task
[2024-02-16T10:01:59.778+0000] {standard_task_runner.py:87} INFO - Running: ['***', 'tasks', 'run', 'our_first_dag_v2', 'second_task', 'manual__2024-02-16T10:01:57.550984+00:00', '--job-id', '5', '--raw', '--subdir', 'DAGS_FOLDER/our_first_dag.py', '--cfg-path', '/tmp/tmpp9y2x1kq']
[2024-02-16T10:01:59.780+0000] {standard_task_runner.py:88} INFO - Job 5: Subtask second_task
[2024-02-16T10:01:59.821+0000] {task_command.py:423} INFO - Running <TaskInstance: our_first_dag_v2.second_task manual__2024-02-16T10:01:57.550984+00:00 [running]> on host 7fa605577889
[2024-02-16T10:01:59.895+0000] {taskinstance.py:2480} INFO - Exporting env vars: AIRFLOW_CTX_DAG_OWNER='Joshua Mutua' AIRFLOW_CTX_DAG_ID='our_first_dag_v2' AIRFLOW_CTX_TASK_ID='second_task' AIRFLOW_CTX_EXECUTION_DATE='2024-02-16T10:01:57.550984+00:00' AIRFLOW_CTX_TRY_NUMBER='1' AIRFLOW_CTX_DAG_RUN_ID='manual__2024-02-16T10:01:57.550984+00:00'
[2024-02-16T10:01:59.896+0000] {subprocess.py:63} INFO - Tmp dir root location: /tmp
[2024-02-16T10:01:59.896+0000] {subprocess.py:75} INFO - Running command: ['/usr/bin/bash', '-c', 'Hey, I am taks2 and i will be running after task 1']
[2024-02-16T10:01:59.903+0000] {subprocess.py:86} INFO - Output:
[2024-02-16T10:01:59.904+0000] {subprocess.py:93} INFO - /usr/bin/bash: line 1: Hey,: command not found
[2024-02-16T10:01:59.905+0000] {subprocess.py:97} INFO - Command exited with return code 127
[2024-02-16T10:01:59.915+0000] {taskinstance.py:2698} ERROR - Task failed with exception
Traceback (most recent call last):
  File "/home/airflow/.local/lib/python3.8/site-packages/airflow/models/taskinstance.py", line 433, in _execute_task
    result = execute_callable(context=context, **execute_callable_kwargs)
  File "/home/airflow/.local/lib/python3.8/site-packages/airflow/operators/bash.py", line 212, in execute
    raise AirflowException(
airflow.exceptions.AirflowException: Bash command failed. The command returned a non-zero exit code 127.
[2024-02-16T10:01:59.918+0000] {taskinstance.py:1138} INFO - Marking task as UP_FOR_RETRY. dag_id=our_first_dag_v2, task_id=second_task, execution_date=20240216T100157, start_date=20240216T100159, end_date=20240216T100159
[2024-02-16T10:01:59.930+0000] {standard_task_runner.py:107} ERROR - Failed to execute job 5 for task second_task (Bash command failed. The command returned a non-zero exit code 127.; 584)
[2024-02-16T10:01:59.952+0000] {local_task_job_runner.py:234} INFO - Task exited with return code 1
[2024-02-16T10:01:59.967+0000] {taskinstance.py:3280} INFO - 0 downstream tasks scheduled from follow-on schedule check
