[2024-02-16T10:04:00.372+0000] {taskinstance.py:1956} INFO - Dependencies all met for dep_context=non-requeueable deps ti=<TaskInstance: our_first_dag_v2.second_task manual__2024-02-16T10:01:57.550984+00:00 [queued]>
[2024-02-16T10:04:00.379+0000] {taskinstance.py:1956} INFO - Dependencies all met for dep_context=requeueable deps ti=<TaskInstance: our_first_dag_v2.second_task manual__2024-02-16T10:01:57.550984+00:00 [queued]>
[2024-02-16T10:04:00.379+0000] {taskinstance.py:2170} INFO - Starting attempt 2 of 6
[2024-02-16T10:04:00.393+0000] {taskinstance.py:2191} INFO - Executing <Task(BashOperator): second_task> on 2024-02-16 10:01:57.550984+00:00
[2024-02-16T10:04:00.395+0000] {standard_task_runner.py:60} INFO - Started process 632 to run task
[2024-02-16T10:04:00.398+0000] {standard_task_runner.py:87} INFO - Running: ['***', 'tasks', 'run', 'our_first_dag_v2', 'second_task', 'manual__2024-02-16T10:01:57.550984+00:00', '--job-id', '6', '--raw', '--subdir', 'DAGS_FOLDER/our_first_dag.py', '--cfg-path', '/tmp/tmpnlr00c31']
[2024-02-16T10:04:00.401+0000] {standard_task_runner.py:88} INFO - Job 6: Subtask second_task
[2024-02-16T10:04:00.443+0000] {task_command.py:423} INFO - Running <TaskInstance: our_first_dag_v2.second_task manual__2024-02-16T10:01:57.550984+00:00 [running]> on host 7fa605577889
[2024-02-16T10:04:00.504+0000] {taskinstance.py:2480} INFO - Exporting env vars: AIRFLOW_CTX_DAG_OWNER='Joshua Mutua' AIRFLOW_CTX_DAG_ID='our_first_dag_v2' AIRFLOW_CTX_TASK_ID='second_task' AIRFLOW_CTX_EXECUTION_DATE='2024-02-16T10:01:57.550984+00:00' AIRFLOW_CTX_TRY_NUMBER='2' AIRFLOW_CTX_DAG_RUN_ID='manual__2024-02-16T10:01:57.550984+00:00'
[2024-02-16T10:04:00.506+0000] {subprocess.py:63} INFO - Tmp dir root location: /tmp
[2024-02-16T10:04:00.506+0000] {subprocess.py:75} INFO - Running command: ['/usr/bin/bash', '-c', 'Hey, I am taks2 and i will be running after task 1']
[2024-02-16T10:04:00.513+0000] {subprocess.py:86} INFO - Output:
[2024-02-16T10:04:00.514+0000] {subprocess.py:93} INFO - /usr/bin/bash: line 1: Hey,: command not found
[2024-02-16T10:04:00.514+0000] {subprocess.py:97} INFO - Command exited with return code 127
[2024-02-16T10:04:00.524+0000] {taskinstance.py:2698} ERROR - Task failed with exception
Traceback (most recent call last):
  File "/home/airflow/.local/lib/python3.8/site-packages/airflow/models/taskinstance.py", line 433, in _execute_task
    result = execute_callable(context=context, **execute_callable_kwargs)
  File "/home/airflow/.local/lib/python3.8/site-packages/airflow/operators/bash.py", line 212, in execute
    raise AirflowException(
airflow.exceptions.AirflowException: Bash command failed. The command returned a non-zero exit code 127.
[2024-02-16T10:04:00.526+0000] {taskinstance.py:1138} INFO - Marking task as UP_FOR_RETRY. dag_id=our_first_dag_v2, task_id=second_task, execution_date=20240216T100157, start_date=20240216T100400, end_date=20240216T100400
[2024-02-16T10:04:00.539+0000] {standard_task_runner.py:107} ERROR - Failed to execute job 6 for task second_task (Bash command failed. The command returned a non-zero exit code 127.; 632)
[2024-02-16T10:04:00.571+0000] {local_task_job_runner.py:234} INFO - Task exited with return code 1
[2024-02-16T10:04:00.585+0000] {taskinstance.py:3280} INFO - 0 downstream tasks scheduled from follow-on schedule check
